<?xml version='1.0'?>

<robot name="my_robot" xmlns:xacro="http://www.ros.org/wiki/xacro">

<xacro:include filename="$(find my_robot)/urdf/my_robot.gazebo" />


  <link name="robot_footprint"></link>

  <joint name="robot_footprint_joint" type="fixed">
    <origin xyz="0 0 0" rpy="0 0 0" />
    <parent link="robot_footprint"/>
    <child link="chassis" />
  </joint>

  <link name='chassis'>
    <pose>0 0 0.1 0 0 0</pose>

    <inertial>
      <mass value="15.0"/>
      <origin xyz="0.0 0 0" rpy=" 0 0 0"/>
      <inertia
          ixx="0.1" ixy="0" ixz="0"
          iyy="0.1" iyz="0"
          izz="0.1"
      />
    </inertial>

    <collision name='collision'>
      <origin xyz="0 0 0" rpy=" 0 0 0"/> 
      <geometry>
        <box size=".5 .4 .16"/>
      </geometry>
    </collision>

    <visual name='chassis_visual'>
      <origin xyz="0 0 0" rpy=" 0 0 0"/>
      <geometry>
        <box size=".5 .4 .16"/>
      </geometry>
    </visual>
  </link>


  <link name='hat'>
    <pose>0 0 0.1 0 0 0</pose>

    <inertial>
      <mass value="15.0"/>
      <origin xyz="0.0 0 0" rpy=" 0 0 0"/>
      <inertia
          ixx="0.1" ixy="0" ixz="0"
          iyy="0.1" iyz="0"
          izz="0.1"
      />
    </inertial>

    <collision name='hat_collision'>
      <origin xyz="0 0 0" rpy=" 0 0 0"/> 
      <geometry>
        <box size=".25 .2 .05"/>
      </geometry>
    </collision>

    <visual name='hat_visual'>
      <origin xyz="0 0 0" rpy=" 0 0 0"/>
      <geometry>
        <box size=".25 .2 .05"/>
      </geometry>
    </visual>
  </link>

  <joint type="fixed" name="hat_joint">
    <axis x="0" y="1" z="0"/>
    <origin xyz="-0.18 0 0.1" rpy="0 0 0"/>
    <child link="hat"/>
    <parent link="chassis"/>
  </joint>

 <link name="f_left_wheel">
    <pose>0 0 0.1 0 0 0</pose>
    <inertial>
      <origin xyz="0 0 0" rpy="0 1.5707 1.5707"/>
      <mass value="5"/>
      <inertia
          ixx="0.1" ixy="0" ixz="0"
          iyy="0.1" iyz="0"
          izz="0.1"
      />
    </inertial>

    <collision name='f_left_wheel_collision'>
     <origin xyz="0 0 0" rpy="0 1.5707 1.5707"/>
      <geometry>
       <cylinder radius="0.1" length="0.05"/>
      </geometry>
    </collision>

    <visual name='f_left_wheel_visual'>
     <origin xyz="0 0 0" rpy="0 1.5707 1.5707"/>
     <geometry>
      <cylinder radius="0.1" length="0.05"/>
     </geometry>
    </visual>

</link>

  <joint type="continuous" name="f_left_wheel_hinge">
    <origin xyz="0.17 0.23 -0.029" rpy="0 0 0"/>
    <child link="f_left_wheel"/>
    <parent link="chassis"/>
    <axis xyz="0 1 0" rpy="0 0 0"/>
    <limit effort="10000" velocity="1000"/>
    <dynamics damping="1.0" friction="1.0"/>
  </joint>

 <link name="b_left_wheel">
    <pose>0 0 0.1 0 0 0</pose>
    <inertial>
      <origin xyz="0 0 0" rpy="0 1.5707 1.5707"/>
      <mass value="5"/>
      <inertia
          ixx="0.1" ixy="0" ixz="0"
          iyy="0.1" iyz="0"
          izz="0.1"
      />
    </inertial>

    <collision name='b_left_wheel_collision'>
     <origin xyz="0 0 0" rpy="0 1.5707 1.5707"/>
      <geometry>
       <cylinder radius="0.1" length="0.05"/>
      </geometry>
    </collision>

    <visual name='b_left_wheel_visual'>
     <origin xyz="0 0 0" rpy="0 1.5707 1.5707"/>
     <geometry>
      <cylinder radius="0.1" length="0.05"/>
     </geometry>
    </visual>

</link>

  <joint type="continuous" name="b_left_wheel_hinge">
    <origin xyz="-0.17 0.23 -0.029" rpy="0 0 0"/>
    <child link="b_left_wheel"/>
    <parent link="chassis"/>
    <axis xyz="0 1 0" rpy="0 0 0"/>
    <limit effort="10000" velocity="1000"/>
    <dynamics damping="1.0" friction="1.0"/>
  </joint>

 <link name="f_right_wheel">
    <inertial>
	<origin xyz="0 0 0" rpy="0 1.5707 1.5707"/>
	<mass value="5"/>
      <inertia
          ixx="0.1" ixy="0" ixz="0"
          iyy="0.1" iyz="0"
          izz="0.1"
      />
    </inertial>

    <collision name='f_right_wheel_collision'>
	<origin xyz="0 0 0" rpy="0 1.5707 1.5707"/>
        <geometry>
         <cylinder radius="0.1" length="0.05"/>
        </geometry>
    </collision>

    <visual name='f_right_wheel_visual'>
	<origin xyz="0 0 0" rpy="0 1.5707 1.5707"/>
        <geometry>
         <cylinder radius="0.1" length="0.05"/>
        </geometry>
    </visual>
</link>

  <joint type="continuous" name="f_right_wheel_hinge">
    <origin xyz="0.17 -0.23 -0.029" rpy="0 0 0"/>
    <child link="f_right_wheel"/>
    <parent link="chassis"/>
    <axis xyz="0 1 0" rpy="0 0 0"/>
    <limit effort="10000" velocity="1000"/>
    <dynamics damping="1.0" friction="1.0"/>
  </joint>

 <link name="b_right_wheel">
    <inertial>
	<origin xyz="0 0 0" rpy="0 1.5707 1.5707"/>
	<mass value="5"/>
      <inertia
          ixx="0.1" ixy="0" ixz="0"
          iyy="0.1" iyz="0"
          izz="0.1"
      />
    </inertial>

    <collision name='b_right_wheel_collision'>
	<origin xyz="0 0 0" rpy="0 1.5707 1.5707"/>
        <geometry>
         <cylinder radius="0.1" length="0.05"/>
        </geometry>
    </collision>

    <visual name='b_right_wheel_visual'>
	<origin xyz="0 0 0" rpy="0 1.5707 1.5707"/>
        <geometry>
         <cylinder radius="0.1" length="0.05"/>
        </geometry>
    </visual>
</link>

  <joint type="continuous" name="b_right_wheel_hinge">
    <origin xyz="-0.17 -0.23 -0.029" rpy="0 0 0"/>
    <child link="b_right_wheel"/>
    <parent link="chassis"/>
    <axis xyz="0 1 0" rpy="0 0 0"/>
    <limit effort="10000" velocity="1000"/>
    <dynamics damping="1.0" friction="1.0"/>
  </joint>


 <link name='camera'>

    <inertial>
	<origin xyz="0 0 0" rpy="0 0 0"/>
    	<mass value="0.1"/>
	<box_inertia
		m="0.1" x="0.05" y="0.05" z="0.05"
	/>
    	  <inertia
    	      ixx="1e-6" ixy="0" ixz="0"
    	      iyy="1e-6" iyz="0"
    	      izz="1e-6"
    	  />
    </inertial>

  <collision name='camera_collision'>
	<origin xyz="0 0 0" rpy="0 0 0"/>
    <geometry>
      <box size="0.05 0.05 0.05"/>
    </geometry>  
  </collision>

  <visual name='camera_visual'>
	<origin xyz="0 0 0" rpy="0 0 0"/>
    <geometry>
      <box size="0.05 0.05 0.05"/>
    </geometry>  
  </visual>
 </link>

  <joint name="camera_joint" type="fixed">
    <axis x="0" y="1" z="0"/>
    <origin xyz="0.275 0 0.0" rpy="0 0 0" />
    <parent link="chassis"/>
    <child link="camera" />
  </joint>

 <link name='hokuyo'>

    <inertial>
	<origin xyz="0 0 0" rpy="0 0 0"/>
    	<mass value="1e-6"/>
    	  <inertia
    	      ixx="1e-6" ixy="0" ixz="0"
    	      iyy="1e-6" iyz="0"
    	      izz="1e-6"
    	  />
    </inertial>

  <collision name='hokuyo_collision'>
	<origin xyz="0 0 0" rpy="0 0 0"/>
    <geometry>
      <box size="0.1 0.1 0.1"/>
    </geometry>  
  </collision>

  <visual name='hokuyo_visual'>
	<origin xyz="0 0 0" rpy="0 0 0"/>
    <geometry>
      <mesh filename="package://my_robot/meshes/hokuyo.dae"/>
    </geometry>  
  </visual>
 </link>

  <joint name="hokuyo_joint" type="fixed">
    <axis x="0" y="1" z="0"/>
    <origin xyz="0.2 0 0.1" rpy="0 0 0" />
    <parent link="chassis"/>
    <child link="hokuyo" />
  </joint>

</robot>

